2020-02-26 17:53:42,140 [INFO ]  Starting Rasa server on http://localhost:5005
2020-02-26 17:54:56,811 [ERROR]  Exception occurred while handling uri: 'http://localhost:5005/favicon.ico'
Traceback (most recent call last):
  File "c:\users\dell\appdata\local\programs\python\python37\lib\site-packages\sanic\app.py", line 918, in handle_request
    handler, args, kwargs, uri = self.router.get(request)
  File "c:\users\dell\appdata\local\programs\python\python37\lib\site-packages\sanic\router.py", line 407, in get
    return self._get(request.path, request.method, "")
  File "c:\users\dell\appdata\local\programs\python\python37\lib\site-packages\sanic\router.py", line 470, in _get
    raise NotFound("Requested URL {} not found".format(url))
sanic.exceptions.NotFound: Requested URL /favicon.ico not found
2020-02-26 17:55:34,019 [ERROR]  Exception occurred while handling uri: 'http://localhost:5005/favicon.ico'
Traceback (most recent call last):
  File "c:\users\dell\appdata\local\programs\python\python37\lib\site-packages\sanic\app.py", line 918, in handle_request
    handler, args, kwargs, uri = self.router.get(request)
  File "c:\users\dell\appdata\local\programs\python\python37\lib\site-packages\sanic\router.py", line 407, in get
    return self._get(request.path, request.method, "")
  File "c:\users\dell\appdata\local\programs\python\python37\lib\site-packages\sanic\router.py", line 470, in _get
    raise NotFound("Requested URL {} not found".format(url))
sanic.exceptions.NotFound: Requested URL /favicon.ico not found
